Workbook
Name _2.5__NRL: #REF!
Name a: #REF!
Name Accountancy_Fees: #REF!
Name Advert: #REF!
Name Answer_E2: [1]Questions!$G$107
Name Answer_E2_Range2: [1]Questions!$G$108
Name Answer_Eapp01: [2]Questions!$G$87
Name Answer_EB2: [2]Questions!$G$247
Name Answer_F2: [1]Questions!$G$114
Name Answer_F2_Range2: [1]Questions!$G$115
Name Answer_F2_Range3: [1]Questions!$G$116
Name Answer_Fapp01: [2]Questions!$G$97
Name Answer_FB2: [2]Questions!$G$250
Name Answer_G2: [1]Questions!$G$123
Name Answer_H2: [1]Questions!$G$129
Name Answer_H2_Range2: [1]Questions!#REF!
Name Answer_HB2: [2]Questions!$G$254
Name Answer_I2: [1]Questions!$G$135
Name Answer_I2_Range2: [1]Questions!$G$136
Name Answer_I2_Range3: [1]Questions!$G$137
Name Answer_I2_Range4: [1]Questions!$G$138
Name Answer_IB2: [2]Questions!$G$257
Name Answer_J2: [1]Questions!$G$147
Name Answer_J2_Range2: [1]Questions!$G$148
Name Answer_J2_Range3: [1]Questions!$G$149
Name Answer_J2_Range4: [1]Questions!$G$152
Name Answer_Japp03: [2]Questions!$G$133
Name Answer_K2: [1]Questions!$G$159
Name Answer_K2_Range2: [1]Questions!$G$160
Name Answer_Kapp01: [2]Questions!$G$141
Name Answer_L2: [1]Questions!$G$166
Name Answer_L2_Range2: [1]Questions!$G$167
Name Answer_L2_Range3: [1]Questions!$G$168
Name Answer_L2_Range4: [1]Questions!$G$171
Name Answer_Lapp03: [2]Questions!$G$154
Name Answer_M2: [1]Questions!$G$178
Name Answer_Mapp01: [2]Questions!$G$161
Name Answer_N2: [1]Questions!$G$184
Name Answer_Napp01: [2]Questions!$G$168
Name Answer_O2: [1]Questions!$G$193
Name Answer_Oapp01: [2]Questions!$G$177
Name Answer_P2: [1]Questions!$G$200
Name Answer_Papp01: [2]Questions!$G$184
Name Answer_R2: [1]Questions!$G$209
Name Answer_R2_Range2: [1]Questions!$G$210
Name Answer_R2_Range3: [1]Questions!$G$211
Name Answer_R2_Range4: [1]Questions!$G$212
Name Answer_Rapp01: [2]Questions!$G$196
Name Answer_S2: [1]Questions!$G$224
Name Answer_T2: [1]Questions!$G$231
Name Answer_U2: [1]Questions!$G$240
Name Answer_V2: [1]Questions!$G$247
Name Answer_W2: [1]Questions!$G$254
Name AskToRefreshProgrammesOnSave: FALSE
Name assets: #REF!
Name ATopicSelected: [1]Questions!$I$7:$I$8
Name ATopicSelected_Yes: [1]Questions!$I$7
Name Audit_Fees: #REF!
Name Bank_Charges: #REF!
Name Bank_Loan: #REF!

Sheet Bilan-18
A3: État de la situation financière | B3: Notes | C3: N | D3: N-1 | E3: N-2
A5: ACTIF
A6: Actifs non courants | B6: 8 | C6: 1078221.7 | D6: 1013250.2 | E6: 199849
A7: Biens, installations et équipements | C7: -------- | D7: ='[4]BS-17'!C8 -> -------- | E7: ='[4]BS-17'!D8 -> --------
C8: =SUM(C6:C7) -> 1078221.7 | D8: =SUM(D6:D7) -> 1013250.2 | E8: =SUM(E6:E7) -> 199849
C9: -------- | D9: ='[4]BS-17'!C10 -> -------- | E9: ='[4]BS-17'!D10 -> --------
D10: 0 | E10: 0
A11: Actifs courants | B11: 9 | C11: 0 | D11: 0 | E11: 0
A12: Inventaire | B12: 10 | C12: 2772095.2 | D12: 1433526.7 | E12: 293946
A13: Créances commerciales et autres créances | C13: 330944.97 | D13: 275512.67 | E13: 5374
A14: Impôts | B14: 11 | C14: 311578.4 | D14: 286298.34 | E14: 64787
A15: Caisse et banque | C15: -------- | D15: ='[4]BS-17'!C16 -> -------- | E15: ='[4]BS-17'!D16 -> --------
C16: =SUM(C11:C15) -> 3414618.5 | D16: =SUM(D11:D15) -> 1995337.7 | E16: =SUM(E11:E15) -> 364107
A17: Total de l'actif circulant | C17: -------- | D17: ='[4]BS-17'!C18 -> -------- | E17: ='[4]BS-17'!D18 -> --------
C18: -------- | D18: ='[4]BS-17'!C19 -> -------- | E18: ='[4]BS-17'!D19 -> --------
C19: =C8+C16 -> 4492840.2 | D19: =D8+D16 -> 3008587.9 | E19: =E8+E16 -> 563956
A20: Total de l'actif | C20: ==== | D20: ==== | E20: ====
D21: 0 | E21: 0
A22: CAPITAL ET PASSIF | D22: 0 | E22: 0
A23: Capital et Réserves | B23: 12 | C23: 200000 | D23: 200000 | E23: 200000
A24: Capital déclaré | C24: 1688079.9 | D24: 482576.2 | E24: 16274
A25: Bénéfices non distribués | C25: -------- | D25: -------- | E25: --------
C26: =SUM(C23:C25) -> 1888079.9 | D26: =SUM(D23:D25) -> 682576.2 | E26: =SUM(E23:E25) -> 216274
A27: Total des fonds propres | C27: -------- | D27: -------- | E27: --------
D28: 0
A29: Passif à long terme | B29: 13 | C29: 0 | D29: 0 | E29: 18328
A30: Prêt bancaire | B30: 14 | C30: 1374983.4 | D30: 1457960.4 | E30: 0
A31: Compte courant des administrateurs | C31: -------- | D31: -------- | E31: --------
C32: =SUM(C29:C31) -> 1374983.4 | D32: =SUM(D29:D31) -> 1457960.4 | E32: =SUM(E29:E31) -> 18328
A33: Total du passif à long terme | C33: -------- | D33: -------- | E33: --------
D34: 0 | E34: 0
A35: Passifs courants | B35: 15 | C35: 1229776.9 | D35: 1229776.9 | E35: 329354
A36: Dettes commerciales et autres dettes | B36: 16 | C36: 0 | D36: 0 | E36: 0
A37: Découvert bancaire | B37: 17 | C37: 0 | D37: 0 | E37: 0
A38: Impôts | C38: -------- | D38: -------- | E38: --------
C39: =SUM(C35:C38) -> 1229776.9 | D39: 868051 | E39: =SUM(E35:E38) -> 329354
A40: Total du passif à court terme | C40: -------- | D40: -------- | E40: --------
C41: -------- | D41: -------- | E41: --------
C42: =C39+C32+C26 -> 4492840.1 | D42: =D39+D32+D26 -> 3008587.6 | E42: =E39+E32+E26 -> 563956
C43: ==== | D43: ==== | E43: ====
...

Sheet CR-18
A2: État du résultat global
B3: Notes | C3: N | D3: N-1 | E3: N-2
A5: Produits des activités ordinaires | B5: 3 | C5: ='[4]Notes-18'!B11 -> 12963693 | D5: ='[4]P&L-17'!C6 -> 11572273 | E5: 3902219
A6: Coût des ventes | B6: 4 | C6: =-'[4]Notes-18'!B23 -> -9590924 | D6: ='[4]P&L-17'!C7 -> -7233199.9 | E6: -2701014
A7: Coûts d'exploitation | C7: 760739.11 | D7: ='[4]P&L-17'!C8 -> -1086470.5 | E7: 0
C8: -------- | D8: -------- | E8: --------
A9: Bénéfice brut | C9: =SUM(C5:C8) -> 4133508.3 | D9: =SUM(D5:D8) -> 3252602.7 | E9: =SUM(E5:E8) -> 1201205
A10: Frais de vente, généraux et administratifs | B10: 5 | C10: =-'[4]Notes-18'!B85 -> -3268767.8 | D10: ='[4]P&L-17'!C11 -> -3103711.8 | E10: -1153111
C11: -------- | D11: -------- | E11: --------
A12: Bénéfice d'exploitation | C12: =C9+C10 -> 864740.46 | D12: =D9+D10 -> 148890.88 | E12: =E9+E10 -> 48094
A13: Autres revenus | B13: 6 | C13: ='[4]Notes-18'!B136 -> 700817.42 | D13: ='[4]P&L-17'!C14 -> 655979.36
C14: -------- | D14: -------- | E14: --------
A15: Bénéfice avant coût financier et impôts | C15: =SUM(C12:C14) -> 1565557.9 | D15: =SUM(D12:D14) -> 804870.24 | E15: =SUM(E12:E14) -> 48094
A16: Coût financier | C16: =-'[4]Notes-17'!B150 -> 0 | D16: =-'[4]Notes-17'!C150 -> 0 | E16: =-'[4]Notes-17'!D150 -> 0
C17: -------- | D17: -------- | E17: --------
A18: Bénéfice avant impôts | C18: =SUM(C15:C17) -> 1565557.9 | D18: =SUM(D15:D17) -> 804870.24 | E18: =SUM(E15:E17) -> 48094
A19: Charge d'impôt sur le revenu | B19: 7 | C19: =-'[4]Notes-18'!B143 -> -360054.21 | D19: ='[4]P&L-17'!C20 -> -163994.84 | E19: -9999
C20: -------- | D20: -------- | E20: --------
A21: Bénéfice de l'année | C21: =SUM(C18:C20) -> 1205503.7 | D21: =SUM(D18:D20) -> 640875.4 | E21: =SUM(E18:E20) -> 38095
A22: Autres éléments du résultat global | C22: 0 | D22: 1 | E22: 2
C23: -------- | D23: -------- | E23: --------
A24: Bénéfices non distribués | C24: =SUM(C21:C23) -> 1205503.7 | D24: =SUM(D21:D23) -> 640876.4 | E24: =SUM(E21:E23) -> 38097
C25: ==== | D25: ==== | E25: ====

Sheet Ratios
A1: Ratios | F1: N | G1: N-1 | H1: N-2
A3: Solvabilité = Fonds propres / actif total (%) | F3: =+'Bilan-18'!C26/'Bilan-18'!C19 -> 0.42024193 | G3: =+'Bilan-18'!D26/'Bilan-18'!D19 -> 0.22687594 | H3: =+'Bilan-18'!E26/'Bilan-18'!E19 -> 0.38349446
A4: Autonomie financière = Fonds propres / capital permanent (%) | F4: =+'Bilan-18'!C26/('Bilan-18'!C26+'Bilan-18'!C32) -> 0.5786219 | G4: =+'Bilan-18'!D26/('Bilan-18'!D26+'Bilan-18'!D32) -> 0.31888088 | H4: =+'Bilan-18'!E26/('Bilan-18'!E26+'Bilan-18'!E32) -> 0.9218762
A6: RATIOS DE RENTABILITÉ ET DE LIQUIDITÉ
A7: Rendement des capitaux propres (ROE) : Bénéfice net / Fonds propres | F7: =+'CR-18'!C21/'Bilan-18'!C26 -> 0.63848129 | G7: =+'CR-18'!D21/'Bilan-18'!D26 -> 0.93890674 | H7: =+'CR-18'!E21/'Bilan-18'!E26 -> 0.1761423
A8: Taux de marge nette (TMN) : Bénéfice net / Chiffre d'affaires | F8: =+'CR-18'!C21/'CR-18'!C5 -> 0.092990759 | G8: =+'CR-18'!D21/'CR-18'!D5 -> 0.055380252 | H8: =+'CR-18'!E21/'CR-18'!E5 -> 0.0097623942
A9: Liquidité générale : Actifs courants / Passifs courants | F9: =+'Bilan-18'!C16/'Bilan-18'!C39 -> 2.7766164 | G9: =+'Bilan-18'!D16/'Bilan-18'!D39 -> 2.2986411 | H9: =+'Bilan-18'!E16/'Bilan-18'!E39 -> 1.1055187
A11: RATIOS D'EFFICACITÉ
A12: Jours de recouvrement moyens (débiteurs divers/recettes d'exploitation * 365 jours) | F12: =(('Bilan-18'!C16-'Bilan-18'!C11)/'CR-18'!C5)*365 -> 96.140486 | G12: =(('Bilan-18'!D16-'Bilan-18'!D11)/'CR-18'!D5)*365 -> 62.934764 | H12: =(('Bilan-18'!E16-'Bilan-18'!E11)/'CR-18'!E5)*365 -> 34.057303
A13: Jours de paiement moyen (Créanciers divers/Achats * 365) | F13: =('Bilan-18'!C35/-'CR-18'!C6)*365 -> 46.801388 | G13: =('Bilan-18'!D35/-'CR-18'!D6)*365 -> 62.056705 | H13: =('Bilan-18'!E35/-'CR-18'!E6)*365 -> 44.507067
A14: Taux de rotation des créances (résultat d'exploitation/débiteurs divers) | F14: =+'CR-18'!C5/('Bilan-18'!C16-'Bilan-18'!C11) -> 3.7965275 | G14: =+'CR-18'!D5/('Bilan-18'!D16-'Bilan-18'!D11) -> 5.7996563 | H14: =+'CR-18'!E5/('Bilan-18'!E16-'Bilan-18'!E11) -> 10.717231
A15: Taux de rotation des stocks (Résultat d'exploitation / Stocks) | F15: ='CR-18'!C5/'Bilan-18'!C11 -> #DIV/0! | G15: ='CR-18'!D5/'Bilan-18'!D11 -> #DIV/0! | H15: ='CR-18'!E5/'Bilan-18'!E11 -> #DIV/0!
A16: Taux de rotation des actifs (Résultat d'exploitation / Actifs immobilisés nets) | F16: =+'CR-18'!C5/'Bilan-18'!C8 -> 12.023217 | G16: =+'CR-18'!D5/'Bilan-18'!D8 -> 11.420944 | H16: =+'CR-18'!E5/'Bilan-18'!E8 -> 19.525837
A18: RATIOS DE LEVIER FINANCIER
A19: Ratio d'endettement ((Emprunts + Dettes à court terme)/Actif total) | F19: =('Bilan-18'!C29+'Bilan-18'!C35)/'Bilan-18'!C42 -> 0.27371925 | G19: =('Bilan-18'!D29+'Bilan-18'!D35)/'Bilan-18'!D42 -> 0.40875554 | H19: =('Bilan-18'!E29+'Bilan-18'!E35)/'Bilan-18'!E42 -> 0.61650554
A20: Ratio d'endettement (Emprunts / Valeur nette) | F20: ='Bilan-18'!C29/'Bilan-18'!C8 -> 0 | G20: ='Bilan-18'!D29/'Bilan-18'!D8 -> 0 | H20: ='Bilan-18'!E29/'Bilan-18'!E8 -> 0.09170924
A21: Passif à court terme / Valeur nette (Passif à court terme / Valeur nette) | F21: ='Bilan-18'!C39/'Bilan-18'!C8 -> 1.1405603 | G21: ='Bilan-18'!D39/'Bilan-18'!D8 -> 0.85669959 | H21: ='Bilan-18'!E39/'Bilan-18'!E8 -> 1.6480143
A22: Ratio de couverture des intérêts (RBE / Charges financières) | F22: ='[5]Income statement'!I37/'[5]Income statement'!I34 -> #DIV/0! | G22: ='[5]Income statement'!J37/'[5]Income statement'!J34 -> #DIV/0! | H22: ='[5]Income statement'!K37/'[5]Income statement'!K34 -> #DIV/0!
A24: RATIOS DE SOLVABILITÉ
A25: Ratio de liquidité générale (actif à court terme / passif à court terme) | F25: ='Bilan-18'!C16/'Bilan-18'!C39 -> 2.7766164 | G25: ='Bilan-18'!D16/'Bilan-18'!D39 -> 2.2986411 | H25: ='Bilan-18'!E16/'Bilan-18'!E39 -> 1.1055187
A26: Ratio de liquidité ((Actifs courants - Stocks) / Passifs courants) | F26: =('Bilan-18'!C16-'Bilan-18'!C11)/'Bilan-18'!C39 -> 2.7766164 | G26: =('Bilan-18'!D16-'Bilan-18'!D11)/'Bilan-18'!D39 -> 2.2986411 | H26: =('Bilan-18'!E16-'Bilan-18'!E11)/'Bilan-18'!E39 -> 1.1055187
A27: Ratio G-Score Financier (Valeur nette / Actif total) | F27: ='Bilan-18'!C8/'Bilan-18'!C19 -> 0.23998665 | G27: ='Bilan-18'!D8/'Bilan-18'!D19 -> 0.33678596 | H27: ='Bilan-18'!E8/'Bilan-18'!E19 -> 0.35436984
A28: Ratio d'endettement G-Score (Dettes / Fonds propres) | F28: ='Bilan-18'!C29/'Bilan-18'!C26 -> 0 | G28: ='Bilan-18'!D29/'Bilan-18'!D26 -> 0 | H28: ='Bilan-18'!E29/'Bilan-18'!E26 -> 0.084744352

Sheet SCORING AVEC BILAN
A1: ACREMAC FAILURE SCORE
A3: BORNES | E3: Coeff. (1) | F3: Ratio | G3: Ratio | H3: Contribution
G4: limited (2) | H4: (1 X 2)
A5: - | B5: Constant | E5: 0.57 | H5: 0.57
A6: [0*;100] | B6: R1 = Financial expenses / EBITDA | E6: 0.0535 | F6: =(+E33) -> 0 | G6: =IF(F6<0,0,IF(F6>100,100,F6)) -> 0 | H6: =+E6*G6 -> 0
A7: [0;200] | B7: R2 = (Receivables+disposables)/Creditors CT | E7: 0.0115 | F7: =(+E37) -> 250.75066 | G7: =IF(F7<0,0,IF(F7>200,200,F7)) -> 200 | H7: =+E7*G7 -> 2.3 | L7: Failure Score
A8: [-25;100] | B8: R3 = Permanent capital / Liabilities | E8: 0.0371 | F8: =(+E41) -> 72.628075 | G8: =IF(F8<-25,-25,IF(F8>100,100,F8)) -> 72.628075 | H8: =+E8*G8 -> 2.6945016
A9: [0;100] | B9: R4 = VA / AC | E9: 0.0246 | F9: =(+E45) -> 31.885268 | G9: =IF(F9<0,0,IF(F9>100,100,F9)) -> 31.885268 | H9: =+E9*G9 -> 0.78437759 | M9: N
A10: [-100;100] | B10: R5 = Cash / Sales (j) | E10: 0.0115 | F10: =+E49 -> 8.6524899 | G10: =IF(F10<-100,-100,IF(F10>100,100,F10)) -> 8.6524899 | H10: =+E10*G10 -> 0.099503634 | J10: The crédit rating is expressed as an rating score with values of 0(Insolvency/preliminary/debt regulation proceedings) to 10 (excellent risk). The rating score denominates the probability of default for the company within 12 months from the date the rating score was set. Credit Rating: 10 Excellent risk, 9 Very low risk, 8 Low risk, 7 Moderate risk, 6 Acceptable risk, 5 Medium high risk, 4 Significant risk, 3 High risk , 2 Very high risk of insolvency, 1 Extremely high risk of insolvency, 0 Insolvency/preliminary/debt regulation proceedings
A11: [-100;150] | B11: R6 = Working capital / CA (j) | E11: 0.0096 | F11: =+E53 -> 4.981628 | G11: =IF(F11<-100,-100,IF(F11>150,150,F11)) -> 4.981628 | H11: =+E11*G11 -> 0.047823629
J14: Insolvency/preliminary/debt regulation proceedings | K14: Very High Risk | N14: Medium High Risk | P14: Low Risk
J15: 0 | K15: 1 | L15: 2 | M15: 3 | N15: 4 | O15: 5 | P15: 6 | Q15: 7 | R15: 8 | S15: 9 | T15: 10
A16: * Negative values are brought back to the upper limit
F18: Value of SCORE | H18: =SUM(H5:H11) -> 6.4962064 | J18: AUTOMATIC SCORE N | M18: =H18 -> 6.4962064
J19: AUTOMATIC SCORE N-1
A20: Score Classes | C20: Probability of failure(%) | E20: Conclusions | J20: AUTOMATIC SCORE N-2
A22: S<-4,01 | C22: >12,7 | J22: MANUAL SCORE N
A23: -4,01<S<-2,57 | C23: 6,00 | E23: High risk (failure rate >10%) | J23: MANUAL SCORE N-1
A24: -2,57<S<-1,00 | C24: 4.96 | J24: MANUAL SCORE N-2
A25: -1,00<S<0,28 | C25: 3.29
A26: 0,28<S<1,26 | C26: 2.15 | E26: Normal risk (default rate = 3%) | J26: Comment:
A27: 1,26<S<2,10 | C27: 1.57
A28: 2,10<S<2,86 | C28: 1.06
A29: 2,86<S<3,68 | C29: 0.64 | E29: Low risk (failure rate < 1%)
A30: 3,68<S<4,83 | C30: 0.38
A31: 5,83<S | C31: <0,42
A33: R1 = Financial expenses / EBITDA | E33: =(+B34/B35)*100 -> 0
A34: FFI | B34: ='CR-18'!C16 -> 0
A35: EBE | B35: ='CR-18'!C15 -> 1565557.9
A37: R2 = (Receivables + Cash) / Liabilities CT | E37: =(+B38/B39)*100 -> 250.75066
A38: Cré+disp net | B38: ='Bilan-18'!C14+'Bilan-18'!C12 -> 3083673.6
A39: CT debts | B39: ='Bilan-18'!C36+'Bilan-18'!C35+'Bilan-18'!C37 -> 1229776.9
A41: R3 = Permanent capital / Liabilities | E41: =(+B42/B43)*100 -> 72.628075
A42: Permanent course | B42: ='Bilan-18'!C32+'Bilan-18'!C26 -> 3263063.3
A43: Liabilities | B43: ='Bilan-18'!C42 -> 4492840.1
A45: R4 = VA / AC | E45: =(+B46/B47)*100 -> 31.885268
A46: VA | B46: ='CR-18'!C9 -> 4133508.3
A47: CA | B47: ='CR-18'!C5 -> 12963693
A49: R5 = Cash / Sales (j) | E49: =(+B50/B51) -> 8.6524899
A50: Treasury | B50: ='Bilan-18'!C14 -> 311578.4
...

Sheet SCORING SANS BILAN
I1: Failure Score
A4: S1:Les locaux | B4: Grille | C4: 0.5 | D4: S4 : Comportement de paiement | E4: Grille | F4: -1
A5: Propriétaire | B5: 1 | D5: A l'avance | E5: 1 | G5: This score is generated automatically through bucrep through the sumilations of the following items: The premises, Age of the company, Payment behaviour, Commercial opinion, Code Nace. The elements of the score grid have been weighted according to their degree of importance in the calculation of the risk. Credit Rating: 10 Excellent risk, 9 Very low risk, 8 Low risk, 7 Moderate risk, 6 Acceptable risk, 5 Medium high risk, 4 Significant risk, 3 High risk , 2 Very high risk of insolvency, 1 Extremely high risk of insolvency, 0 Insolvency/preliminary/debt regulation proceedings
A6: Locataire | B6: 0.5 | D6: Dans les délais | E6: 0.5
D7: En retard | E7: 0
D8: Normal | E8: 0.25 | G8: Insolvency/preliminary/debt regulation proceedings | H8: Very High Risk | K8: Medium High Risk | M8: Low Risk
A9: S2 : Forme juridique | B9: Grille | C9: 0.003 | D9: Mauvais payeur | E9: -1 | G9: 0 | H9: 1 | I9: 2 | J9: 3 | K9: 4 | L9: 5 | M9: 6 | N9: 7 | O9: 8 | P9: 9 | Q9: 10
A10: Société anonyme | B10: 1 | D10: Inconnu | E10: 0 | G10: ↑ | H10: ↑ | I10: ↑ | J10: ↑ | K10: ↑ | L10: ↑ | M10: ↑ | N10: ↑ | O10: ↑ | P10: ↑ | Q10: ↑
A11: Société à responsabilité limitée(SARL | B11: 0.75 | D11: Plainte isolée | E11: 0
A12: Entreprise individuelle(EI) | B12: 0.05 | G12: AUTOMATIC SCORE | I12: =+C4+C9+C18+F4+F13+F19 -> 0.003
A13: Société à responsabilité limitée unipersonnelle(SARL U) | B13: 0;50 | D13: S5 : Avis commercial | E13: Grille | F13: 0 | J13: =ROUNDDOWN(I12,0) -> 0
A14: Succursale | B14: 0.005 | D14: Négatif | E14: 0
A15: Organisme public | B15: 0.005 | D15: Moyen | E15: 0.25
A16: Autre forme juridique | B16: 0.003 | D16: Bon | E16: 0.5
D17: Très bonne | E17: 0.75
A18: S3 : Âge de l'entreprise | B18: Grille | C18: 0
A19: Nouvelle entreprise | B19: 0 | D19: S6 : Code Nace | E19: Grille | F19: 0.5
A20: ≤ 2 ans | B20: 0.1 | D20: Manifacture | E20: 0.75
A21: 2-4 ans | B21: 0.2 | D21: Commerce de gros | E21: 0.5
A22: 5-6 ans | B22: 0.4 | D22: Services | E22: 0.5
A23: 7-8 ans | B23: 0.6
A24: 9-10 ans | B24: 0.8
A25: < 10 ans | B25: 1
