Workbook

Sheet ACTIF
B1: ACTIF | E1: NOTE
G2: EXERCICE | H2: EXERCICE | I2: EXERCICE | J2: VARIATION
F3: BRUT | G3: N | H3: N-1 | I3: N-2 | J3: N/N-1
B4: IMMOBILISATIONS INCORPORELLES | E4: 3 | F4: =SUM(F5:F8) -> 0 | G4: =SUM(G5:G8) -> 0 | H4: =SUM(H5:H8) -> 0 | I4: =SUM(I5:I8) -> 0 | J4: =(G4-H4)/H4 -> #DIV/0!
B5: Frais de développement et de prospection | F5: 0 | G5: 0 | H5: 0 | I5: 0 | J5: =(G5-H5)/H5 -> #DIV/0!
B6: Brevets, licences, logiciels et droits similaires | F6: 0 | G6: 0 | H6: 0 | I6: 0 | J6: =(G6-H6)/H6 -> #DIV/0!
B7: Droit de la propriété commerciale et des baux | F7: 0 | G7: 0 | H7: 0 | I7: 0 | J7: =(G7-H7)/H7 -> #DIV/0!
B8: Autres immobilisations incorporelles | F8: 0 | G8: 0 | H8: 0 | I8: 0 | J8: =(G8-H8)/H8 -> #DIV/0!
B9: IMMOBILISATIONS CORPORELLES | E9: 3 | F9: =SUM(F10:F16) -> 72585000 | G9: =SUM(G10:G16) -> 2125000 | H9: =SUM(H10:H16) -> 2815000 | I9: =SUM(I10:I16) -> 7225000 | J9: =(G9-H9)/H9 -> -0.24511545
B10: Terrains (1) | F10: 15000000 | G10: 0 | H10: 0 | I10: 0 | J10: =(G10-H10)/H10 -> #DIV/0!
B11: _x000D_ dont investissement net. | G11: 0 | H11: 0 | I11: 0 | J11: =(G11-H11)/H11 -> #DIV/0!
B12: Bâtiments (1) | F12: 25000000 | G12: 0 | H12: 0 | I12: 0 | J12: =(G12-H12)/H12 -> #DIV/0!
B13: dont investissement net | G13: 0 | H13: 0 | I13: 0 | J13: =(G13-H13)/H13 -> #DIV/0!
B14: Agencements, aménagements et installations | F14: 0 | G14: 2125000 | H14: 2550000 | I14: 4825000 | J14: =(G14-H14)/H14 -> -0.16666667
B15: Matériel, mobilier et actifs biologiques | F15: 2122500 | G15: 0 | H15: 265000 | I15: 2400000 | J15: =(G15-H15)/H15 -> -1
B16: Matériel de transport | F16: 30462500 | G16: 0 | H16: 0 | I16: 0 | J16: =(G16-H16)/H16 -> #DIV/0!
B17: AVANCES ET ACOMPTES SUR IMMOBILISATIONS | E17: 3 | F17: 0 | G17: 0 | H17: 0 | I17: 0 | J17: =(G17-H17)/H17 -> #DIV/0!
B18: IMMOBILISATIONS FINANCIÈRES | E18: 4 | F18: =SUM(F19:F20) -> #VALUE! | G18: =SUM(G19:G20) -> 3000000 | H18: =SUM(H19:H20) -> 3000000 | I18: =SUM(I19:I20) -> 3000000 | J18: =(G18-H18)/H18 -> 0
B19: Titres de participation | F19: =SUMIF('[1]BG N'!A:A,$A19,'[1]BG N'!K:K) -> #VALUE! | G19: 0 | H19: 0 | I19: 0 | J19: =(G19-H19)/H19 -> #DIV/0!
B20: Autres immobilisations financières | F20: =SUMIF('[1]BG N'!A:A,$A20,'[1]BG N'!K:K) -> #VALUE! | G20: 3000000 | H20: 3000000 | I20: 3000000 | J20: =(G20-H20)/H20 -> 0
B21: TOTAL DE L'ACTIF IMMOBILISÉ | F21: =F4+F9+F17+F18 -> #VALUE! | G21: =G4+G9+G17+G18 -> 5125000 | H21: =H4+H9+H17+H18 -> 5815000 | I21: =I4+I9+I17+I18 -> 10225000 | J21: =(G21-H21)/H21 -> -0.11865864
B22: ACTIF CIRCULANT DE HAO | E22: 5 | F22: 0 | G22: 0 | H22: 0 | I22: 0 | J22: =(G22-H22)/H22 -> #DIV/0!
B23: STOCKS ET EN-COURS | E23: 6 | F23: 91214256 | G23: 52315000 | H23: 44447550 | I23: 38654000 | J23: =(G23-H23)/H23 -> 0.17700526
B24: CRÉANCES ET EMPLOIS SIMILAIRES | F24: =SUM(F25:F27) -> 1.607179e+08 | G24: =SUM(G25:G27) -> 24245000 | H24: =SUM(H25:H27) -> 21242051 | I24: =SUM(I25:I27) -> 30739000 | J24: =(G24-H24)/H24 -> 0.14136813
B25: Fournisseurs avances versées | E25: 17 | F25: 0 | G25: 0 | H25: 0 | I25: 0 | J25: =(G25-H25)/H25 -> #DIV/0!
B26: Clients | E26: 7 | F26: 67603814 | G26: 24245000 | H26: 21242051 | I26: 30739000 | J26: =(G26-H26)/H26 -> 0.14136813
B27: Autres créances | E27: 8 | F27: 93114085 | G27: 0 | H27: 0 | I27: 0 | J27: =(G27-H27)/H27 -> #DIV/0!
B28: TOTAL DE L'ACTIF CIRCULANT | F28: =F22+F23+F24 -> 2.5193216e+08 | G28: =G22+G23+G24 -> 76560000 | H28: =H22+H23+H24 -> 65689601 | I28: =I22+I23+I24 -> 69393000 | J28: =(G28-H28)/H28 -> 0.16548128
B29: Valeurs mobilières de placement | F29: 0 | G29: 0 | H29: 0 | I29: 0 | J29: =(G29-H29)/H29 -> #DIV/0!
B30: Disponibilités | F30: 0 | G30: 0 | H30: 0 | I30: 0 | J30: =(G30-H30)/H30 -> #DIV/0!
B31: Banque, chèque postal, caisse et assimilés | E31: 11 | F31: 52229246 | G31: 3254000 | H31: 5423000 | I31: 7235000 | J31: =(G31-H31)/H31 -> -0.39996312
B32: TOTAL DE LA TRÉSORERIE ET DES ÉQUIVALENTS DE TRÉSORERIE | F32: =SUM(F29:F31) -> 52229246 | G32: =SUM(G29:G31) -> 3254000 | H32: =SUM(H29:H31) -> 5423000 | I32: =SUM(I29:I31) -> 7235000 | J32: =(G32-H32)/H32 -> -0.39996312
B33: Écart de conversion - Actif | E33: 12 | F33: 0 | G33: 0 | H33: 0 | I33: 0 | J33: =(G33-H33)/H33 -> #DIV/0!
B34: TOTAL ACTIF | F34: =F21+F28+F32+F33 -> #VALUE! | G34: =G21+G28+G32+G33 -> 84939000 | H34: =H21+H28+H32+H33 -> 76927601 | I34: =I21+I28+I32+I33 -> 86853000 | J34: =(G34-H34)/H34 -> 0.10414206

Sheet PASSIF
A1: Réf. | B1: PASSIF | C1: Note | D1: EXERCICE | E1: EXERCICE | F1: EXERCICE
D2: N | E2: N-1 | F2: N-2
D3: NET | E3: NET | F3: NET
A4: CA | B4: Capital | C4: 13 | D4: 42687971 | E4: 37702931 | F4: 41016000
A5: CB | B5: Capital non appelé des apporteurs (-) | C5: 13 | D5: 0 | E5: 0 | F5: 0
A6: CD | B6: Primes liées au capital social | C6: 14 | D6: 0 | E6: 0 | F6: 0
A7: CE | B7: Ecarts de réévaluation | C7: 3e | D7: 0 | E7: 0 | F7: 0
A8: CF | B8: Réserves indisponibles | C8: 14 | D8: 0 | E8: 0 | F8: 0
A9: CG | B9: Réserves libres | C9: 14 | D9: 0 | E9: 0 | F9: 0
A10: CH | B10: Report à nouveau (+ ou -) | C10: 14 | D10: 0 | E10: 0 | F10: 0
A11: CJ | B11: Résultat net de l'exercice (bénéfice + perte -) | D11: 29038715 | E11: 21233380 | F11: 31603000
A12: CL | B12: Subventions d'investissement | C12: 15 | D12: 0 | E12: 0 | F12: 0
A13: CM | B13: Provisions réglées | C13: 15 | D13: 0 | E13: 0 | F13: 0
A14: CP | B14: TOTAL DES CAPITAUX PROPRES ET RESSOURCES SIMILAIRES | D14: =SUM(D4:D13) -> 71726686 | E14: =SUM(E4:E13) -> 58936311 | F14: =SUM(F4:F13) -> 72619000
A15: DA | B15: Emprunts et dettes financières diverses | C15: 16 | D15: 0 | E15: 0 | F15: 0
A16: DB | B16: Dettes de location-vente | C16: 16 | D16: 0 | E16: 0 | F16: 0
A17: DC | B17: Provisions pour risques et charges | C17: 16 | D17: 0 | E17: 0 | F17: 0
A18: DD | B18: TOTAL DES DETTES FINANCIÈRES ET RESSOURCES ASSIMILÉES | D18: =SUM(D15:D17) -> 0 | E18: =SUM(E15:E17) -> 0 | F18: =SUM(F15:F17) -> 0
A19: DF | B19: TOTAL DES RESSOURCES STABLES | D19: =D14+D18 -> 71726686 | E19: =E14+E18 -> 58936311 | F19: =F14+F18 -> 72619000
A20: DH | B20: Passif circulant HAO | C20: 5 | D20: 0 | E20: 0 | F20: 0
A21: DI | B21: Clients, avances reçues | C21: 7 | F21: 0
A22: DJ | B22: Fournisseurs d'exploitation | C22: 17 | D22: 6854000 | E22: 13688676 | F22: 13255000
A23: DK | B23: Dettes fiscales et sociales | C23: 18 | D23: 2106412 | E23: 1315825 | F23: =865000+114000 -> 979000
A24: DM | B24: Autres dettes | C24: 19 | D24: 0 | E24: 0 | F24: 0
A25: DN | B25: Provisions pour risques à court terme | C25: 19 | D25: 0 | E25: 0 | F25: 0
A26: DP | B26: TOTAL DES PASSIFS COURANTS | D26: =SUM(D20:D25) -> 8960412 | E26: =SUM(E20:E25) -> 15004501 | F26: =SUM(F20:F25) -> 14234000
A27: DQ | B27: Banques, crédits d'escompte | C27: 20 | D27: 0 | E27: 0 | F27: 0
A28: DR | B28: Banques, établissements financiers et crédits de caisse | C28: 20 | D28: 4251902 | E28: 2986789 | F28: 0
A29: DT | B29: TOTAL DE LA TRÉSORERIE ET DES ÉQUIVALENTS DE TRÉSORERIE | D29: =SUM(D27:D28) -> 4251902 | E29: =SUM(E27:E28) -> 2986789 | F29: =SUM(F27:F28) -> 0
A30: DV | B30: Ecarts de conversion - Passif | C30: 12 | D30: 0 | E30: 0 | F30: 0
A31: DZ | B31: TOTAL DES PASSIFS | D31: =D19+D26+D29+D30 -> 84939000 | E31: =E19+E26+E29+E30 -> 76927601 | F31: =F19+F26+F29+F30 -> 86853000

Sheet COMPTE DE RESULTAT
A1: Réf | B1: Compte de résultat | H1: NOTE | I1: EXERCICE | J1: EXERCICE | K1: EXERCICE
I2: N | J2: N-1 | K2: N-2
I3: NET | J3: NET | K3: NET
A4: TA | B4: Ventes de marchandises A | F4: + | G4: 1 | H4: 21 | I4: 308158920 | J4: 224653915 | K4: 489605000
A5: RA | B5: Achats de marchandises | F5: - | G5: -1 | H5: 22 | I5: 260652475 | J5: 182314905 | K5: 393265000
A6: RB | B6: Variation des stocks de marchandises | F6: -/+ | G6: 1 | H6: 6 | I6: 7867450 | J6: 4125650 | K6: 1696000
A7: XA | B7: MARGE COMMERCIALE (Somme TA à RB) | I7: =I6*G6+I5*G5+I4*G4 -> 55373895 | J7: =J6*G6+J5*G5+J4*G4 -> 46464660 | K7: =K6*G6+K5*G5+K4*G4 -> 98036000
A8: TB | B8: Ventes de produits manufacturés B | F8: + | G8: 1 | H8: 21 | I8: 0 | J8: 0 | K8: 0
A9: TC | B9: Travaux, services vendus C | F9: + | G9: 1 | H9: 21 | I9: 0 | J9: 0 | K9: 0
A10: TD | B10: Produits accessoires D | F10: + | G10: 1 | H10: 21 | I10: 0 | J10: 0 | K10: 0
A11: XB | B11: CHIFFRE D'AFFAIRES (A+B+C+D) | I11: =I4*G4+I8*G8+I9*G9+I10*G10 -> 308158920 | J11: =J4*G4+J8*G8+J9*G9+J10*G10 -> 224653915 | K11: =K4*G4+K8*G8+K9*G9+K10*G10 -> 489605000
A12: TE | B12: Production stockée (ou déstockage) | F12: -/+ | G12: 1 | H12: 6 | I12: 0 | J12: 0 | K12: 0
A13: TF | B13: Production immobilisée | F13: + | G13: 1 | H13: 21 | I13: 0 | J13: 0 | K13: 0
A14: TG | B14: Subvention d'exploitation | F14: + | G14: 1 | H14: 21 | I14: 0 | J14: 0 | K14: 0
A15: TH | B15: Autres produits | F15: + | G15: 1 | H15: 21 | I15: 0 | J15: 0 | K15: 0
A16: TI | B16: Transfert de charges d'exploitation | F16: + | G16: 1 | H16: 12 | I16: 0 | J16: 0 | K16: 0
A17: RC | B17: Achats de matières premières et fournitures connexes | F17: - | G17: -1 | H17: 22 | I17: 0 | J17: 0 | K17: 0
A18: RD | B18: Variation des stocks de matières premières et fournitures connexes | F18: -/+ | G18: 1 | H18: 6 | I18: 0 | J18: 0 | K18: 0
A19: RE | B19: Autres achats | F19: - | G19: -1 | H19: 22 | I19: 3883900 | J19: 3512137 | K19: 22305000
A20: RF | B20: Variation des stocks d'autres fournitures | F20: -/+ | G20: 1 | H20: 6 | I20: 0 | J20: 0 | K20: 0
A21: RG | B21: Transport | F21: - | G21: -1 | H21: 23 | I21: 274500 | J21: 1178835 | K21: 5423000
A22: RH | B22: Services extérieurs | F22: - | G22: -1 | H22: 24 | I22: 7638665 | J22: 5576965 | K22: 13453000
A23: RI | B23: Impôts et taxes | F23: - | G23: -1 | H23: 25 | I23: 136500 | J23: 1275370 | K23: 1631000
A24: RJ | B24: Autres dépenses | F24: - | G24: -1 | H24: 26 | I24: 0 | J24: 0 | K24: 0
A25: XC | B25: VALEUR AJOUTÉE (XB+RA+RB) + (Somme TE à RJ) | I25: =I11+(I5*G5)+(I6*G6)+(I24*G24)+(I23*G23)+(I22*G22)+(I21*G21)+(I20*G20)+(I19*G19)+(I18*G18)+(I17*G17)+(I16*G16)+(I15*G15)+(I14*G14)+(I13*G13)+(I12*G12) -> 43440330 | J25: =J11+(J5*G5)+(J6*G6)+(J24*G24)+(J23*G23)+(J22*G22)+(J21*G21)+(J20*G20)+(J19*G19)+(J18*G18)+(J17*G17)+(J16*G16)+(J15*G15)+(J14*G14)+(J13*G13)+(J12*G12) -> 34921353 | K25: =K11+(K5*G5)+(K6*G6)+(K24*G24)+(K23*G23)+(K22*G22)+(K21*G21)+(K20*G20)+(K19*G19)+(K18*G18)+(K17*G17)+(K16*G16)+(K15*G15)+(K14*G14)+(K13*G13)+(K12*G12) -> 55224000
A26: RK | B26: Frais de personnel | F26: - | G26: -1 | H26: 27 | I26: 5000000 | J26: 5000000 | K26: 8450000
A27: XD | B27: EXCÉDENT BRUT D'EXPLOITATION | H27: 28 | I27: =I25+(I26*G26) -> 38440330 | J27: =+J25+(J26*G26) -> 29921353 | K27: =+K25+(K26*G26) -> 46774000
A28: TJ | B28: Reprises de dépréciations, amortissements, provisions et pertes de valeur | F28: + | G28: 1 | H28: 28 | I28: 0 | J28: 0 | K28: 0
A29: RL | B29: Reprises de dépréciations, amortissements, provisions et pertes de valeur | F29: - | G29: -1 | H29: 3C&28 | I29: 690000 | J29: 690000 | K29: 1590000
A30: XE | B30: RÉSULTAT D'EXPLOITATION (XD+TJ+RL) | I30: =+I27+(I28*G28)+(I29*G29) -> 37750330 | J30: =+J27+(J28*G28)+(J29*G29) -> 29231353 | K30: =+K27+(K28*G28)+(K29*G29) -> 45184000
A31: TK | B31: Produits financiers et assimilés | F31: + | G31: 1 | H31: 29 | I31: 0 | J31: 0 | K31: 0
A32: TL | B32: Reprises sur provisions et pertes de valeur | F32: + | G32: 1 | H32: 28 | I32: 0 | J32: 0 | K32: 0
A33: TM | B33: Transfert de charges financières | F33: + | G33: 1 | H33: 12 | I33: 0 | J33: 0 | K33: 0
A34: RM | B34: Charges financières et assimilées | F34: - | G34: -1 | H34: 29 | I34: 0 | J34: 0 | K34: 0
A35: RN | B35: Dotations aux provisions et dépréciations financières | F35: - | G35: -1 | H35: 3C&28 | I35: 0 | J35: 0 | K35: 0
A36: XF | B36: RÉSULTAT FINANCIER (Somme TK à RN) | I36: =(I35*G35)+(I34*G34)+(I33*G33)+(I32*G32)+(I31*G31) -> 0 | J36: =(J35*G35)+(J34*G34)+(J33*G33)+(J32*G32)+(J31*G31) -> 0 | K36: =(K35*G35)+(K34*G34)+(K33*G33)+(K32*G32)+(K31*G31) -> 0
A37: XG | B37: RÉSULTAT DES ACTIVITÉS ORDINAIRES (XE+XF) | I37: =+I30+I36 -> 37750330 | J37: =+J30+J36 -> 29231353 | K37: =+K30+K36 -> 45184000
A38: TN | B38: Produits des cessions d'immobilisations | F38: + | G38: 1 | H38: 3D | I38: 0 | J38: 0 | K38: 0
A39: TO | B39: Autres produits HAO | F39: + | G39: 1 | H39: 30 | I39: 0 | J39: 0 | K39: 0
A40: RO | B40: Valeur comptable des cessions d'actifs immobilisés | F40: - | G40: -1 | H40: 3D | I40: 0 | J40: 0 | K40: 0
...

Sheet Ratios
A1: Ratios
F2: N | G2: N-1 | H2: N-2
A3: WC (Working capital) = K perm - Actif net Immob | F3: =PASSIF!D19-ACTIF!G21 -> 66601686 | G3: =PASSIF!E19-ACTIF!H21 -> 53121311 | H3: =PASSIF!F19-ACTIF!I21 -> 62394000
A4: NWC (Need for working capital) = Actif circ - Passif circ | F4: =ACTIF!G28-PASSIF!D26 -> 67599588 | G4: =ACTIF!H28-PASSIF!E26 -> 50685100 | H4: =ACTIF!I28-PASSIF!F26 -> 55159000
A5: NCP (Net Cash Position) = FR - BFR | F5: =F3-F4 -> -997902 | G5: =G3-G4 -> 2436211 | H5: =H3-H4 -> 7235000
A6: CAF (Self-financing capacity) = EBITDA + Cashable products - Non cash charge | F6: =('COMPTE DE RESULTAT'!I27+'COMPTE DE RESULTAT'!I4+'COMPTE DE RESULTAT'!I8+'COMPTE DE RESULTAT'!I9+'COMPTE DE RESULTAT'!I10+'COMPTE DE RESULTAT'!I15+'COMPTE DE RESULTAT'!I31+'COMPTE DE RESULTAT'!I32+'COMPTE DE RESULTAT'!I33-'COMPTE DE RESULTAT'!I5-'COMPTE DE RESULTAT'!I17-'COMPTE DE RESULTAT'!I19-'COMPTE DE RESULTAT'!I21-'COMPTE DE RESULTAT'!I22-'COMPTE DE RESULTAT'!I23-'COMPTE DE RESULTAT'!I24-'COMPTE DE RESULTAT'!I26-'COMPTE DE RESULTAT'!I40-'COMPTE DE RESULTAT'!I41-'COMPTE DE RESULTAT'!I34-'COMPTE DE RESULTAT'!I35) -> 69013210 | G6: =('COMPTE DE RESULTAT'!J27+'COMPTE DE RESULTAT'!J4+'COMPTE DE RESULTAT'!J8+'COMPTE DE RESULTAT'!J9+'COMPTE DE RESULTAT'!J10+'COMPTE DE RESULTAT'!J15+'COMPTE DE RESULTAT'!J31+'COMPTE DE RESULTAT'!J32+'COMPTE DE RESULTAT'!J33-'COMPTE DE RESULTAT'!J5-'COMPTE DE RESULTAT'!J17-'COMPTE DE RESULTAT'!J19-'COMPTE DE RESULTAT'!J21-'COMPTE DE RESULTAT'!J22-'COMPTE DE RESULTAT'!J23-'COMPTE DE RESULTAT'!J24-'COMPTE DE RESULTAT'!J26-'COMPTE DE RESULTAT'!J40-'COMPTE DE RESULTAT'!J41-'COMPTE DE RESULTAT'!J34-'COMPTE DE RESULTAT'!J35) -> 55717056 | H6: =('COMPTE DE RESULTAT'!K27+'COMPTE DE RESULTAT'!K4+'COMPTE DE RESULTAT'!K8+'COMPTE DE RESULTAT'!K9+'COMPTE DE RESULTAT'!K10+'COMPTE DE RESULTAT'!K15+'COMPTE DE RESULTAT'!K31+'COMPTE DE RESULTAT'!K32+'COMPTE DE RESULTAT'!K33-'COMPTE DE RESULTAT'!K5-'COMPTE DE RESULTAT'!K17-'COMPTE DE RESULTAT'!K19-'COMPTE DE RESULTAT'!K21-'COMPTE DE RESULTAT'!K22-'COMPTE DE RESULTAT'!K23-'COMPTE DE RESULTAT'!K24-'COMPTE DE RESULTAT'!K26-'COMPTE DE RESULTAT'!K40-'COMPTE DE RESULTAT'!K41-'COMPTE DE RESULTAT'!K34-'COMPTE DE RESULTAT'!K35) -> 91852000
F24: N | G24: N-1 | H24: N-2
A25: Solvency = Shareholders' equity/T total asset (%) | F25: =PASSIF!D14/ACTIF!G34 -> 0.84444938 | G25: =PASSIF!E14/PASSIF!E31 -> 0.76612698 | H25: =PASSIF!F14/PASSIF!F31 -> 0.83611389
A26: Financial autonomy = Shareholders' equity / permanent capital (%) | F26: =+PASSIF!D14/PASSIF!D19 -> 1 | G26: =+PASSIF!E14/PASSIF!E19 -> 1 | H26: =+PASSIF!F14/PASSIF!F19 -> 1
A41: Profitability ratios | F41: N | G41: N-1 | H41: N-2
A42: Return on equity (ROE): Net profit / Shareholders' equity | F42: ='COMPTE DE RESULTAT'!I45/PASSIF!D14 -> 0.40485232 | G42: ='COMPTE DE RESULTAT'!J45/PASSIF!E14 -> 0.36027671 | H42: ='COMPTE DE RESULTAT'!K45/PASSIF!F14 -> 0.43517537
A43: Return on Activity (ROA): Self-financing capacity / turnover | F43: =('COMPTE DE RESULTAT'!I27+'COMPTE DE RESULTAT'!I4+'COMPTE DE RESULTAT'!I8+'COMPTE DE RESULTAT'!I9+'COMPTE DE RESULTAT'!I10+'COMPTE DE RESULTAT'!I15+'COMPTE DE RESULTAT'!I31+'COMPTE DE RESULTAT'!I32+'COMPTE DE RESULTAT'!I33-'COMPTE DE RESULTAT'!I5-'COMPTE DE RESULTAT'!I17-'COMPTE DE RESULTAT'!I19-'COMPTE DE RESULTAT'!I21-'COMPTE DE RESULTAT'!I22-'COMPTE DE RESULTAT'!I23-'COMPTE DE RESULTAT'!I24-'COMPTE DE RESULTAT'!I26-'COMPTE DE RESULTAT'!I40-'COMPTE DE RESULTAT'!I41-'COMPTE DE RESULTAT'!I34-'COMPTE DE RESULTAT'!I35)/'COMPTE DE RESULTAT'!I11 -> 0.22395331 | G43: =('COMPTE DE RESULTAT'!J27+'COMPTE DE RESULTAT'!J4+'COMPTE DE RESULTAT'!J8+'COMPTE DE RESULTAT'!J9+'COMPTE DE RESULTAT'!J10+'COMPTE DE RESULTAT'!J15+'COMPTE DE RESULTAT'!J31+'COMPTE DE RESULTAT'!J32+'COMPTE DE RESULTAT'!J33-'COMPTE DE RESULTAT'!J5-'COMPTE DE RESULTAT'!J17-'COMPTE DE RESULTAT'!J19-'COMPTE DE RESULTAT'!J21-'COMPTE DE RESULTAT'!J22-'COMPTE DE RESULTAT'!J23-'COMPTE DE RESULTAT'!J24-'COMPTE DE RESULTAT'!J26-'COMPTE DE RESULTAT'!J40-'COMPTE DE RESULTAT'!J41-'COMPTE DE RESULTAT'!J34-'COMPTE DE RESULTAT'!J35)/'COMPTE DE RESULTAT'!J11 -> 0.24801284 | H43: =('COMPTE DE RESULTAT'!K27+'COMPTE DE RESULTAT'!K4+'COMPTE DE RESULTAT'!K8+'COMPTE DE RESULTAT'!K9+'COMPTE DE RESULTAT'!K10+'COMPTE DE RESULTAT'!K15+'COMPTE DE RESULTAT'!K31+'COMPTE DE RESULTAT'!K32+'COMPTE DE RESULTAT'!K33-'COMPTE DE RESULTAT'!K5-'COMPTE DE RESULTAT'!K17-'COMPTE DE RESULTAT'!K19-'COMPTE DE RESULTAT'!K21-'COMPTE DE RESULTAT'!K22-'COMPTE DE RESULTAT'!K23-'COMPTE DE RESULTAT'!K24-'COMPTE DE RESULTAT'!K26-'COMPTE DE RESULTAT'!K40-'COMPTE DE RESULTAT'!K41-'COMPTE DE RESULTAT'!K34-'COMPTE DE RESULTAT'!K35)/'COMPTE DE RESULTAT'!K11 -> 0.18760429
A44: Net Margin Rate (NMR): Net profit/ Turnover | F44: ='COMPTE DE RESULTAT'!I45/'COMPTE DE RESULTAT'!I11 -> 0.09423292 | G44: ='COMPTE DE RESULTAT'!J45/'COMPTE DE RESULTAT'!J11 -> 0.094515958 | H44: ='COMPTE DE RESULTAT'!K45/'COMPTE DE RESULTAT'!K11 -> 0.064545909
A45: Gross margin rate: EBITDA / Turnover | F45: ='COMPTE DE RESULTAT'!I27/'COMPTE DE RESULTAT'!I11 -> 0.1247419 | G45: ='COMPTE DE RESULTAT'!J27/'COMPTE DE RESULTAT'!J11 -> 0.13318866 | H45: ='COMPTE DE RESULTAT'!K27/'COMPTE DE RESULTAT'!K11 -> 0.095534155
A66: Liquidity ratios | F66: N | G66: N-1 | H66: N-2
A67: General liquidity : Current assets / Current liabilities | F67: =ACTIF!G28/PASSIF!D26 -> 8.54425 | G67: =ACTIF!H28/PASSIF!E26 -> 4.377993 | H67: =ACTIF!I28/PASSIF!F26 -> 4.8751581
A68: Restricted liquidity : (Receivables + cash and cash equivalents) / short-term debts | F68: =(ACTIF!G24+ACTIF!G32)/PASSIF!D26 -> 3.0689437 | G68: =(ACTIF!H24+ACTIF!H32)/PASSIF!E26 -> 1.7771368 | H68: =(ACTIF!I24+ACTIF!I32)/PASSIF!F26 -> 2.6678376
A69: Immediate liquidity : Cash/Short-term debt | F69: =ACTIF!G32/PASSIF!D26 -> 0.36315294 | G69: =ACTIF!H32/PASSIF!E26 -> 0.36142488 | H69: =ACTIF!I32/PASSIF!F26 -> 0.50829001
A92: EFFICIENCY RATIOS | F92: N | G92: N-1 | H92: N-2
A93: Average Collection Days :(Sundry Debtors/Operating Income * 365 Days) | F93: =((ACTIF!G24/('COMPTE DE RESULTAT'!I11+'COMPTE DE RESULTAT'!I15+'COMPTE DE RESULTAT'!I16+'COMPTE DE RESULTAT'!I14+'COMPTE DE RESULTAT'!I13))*365) -> 28.717082 | G93: =((ACTIF!H24/('COMPTE DE RESULTAT'!J11+'COMPTE DE RESULTAT'!J15+'COMPTE DE RESULTAT'!J16+'COMPTE DE RESULTAT'!J14+'COMPTE DE RESULTAT'!J13))*365) -> 34.512413 | H93: =((ACTIF!I24/('COMPTE DE RESULTAT'!K11+'COMPTE DE RESULTAT'!K15+'COMPTE DE RESULTAT'!K16+'COMPTE DE RESULTAT'!K14+'COMPTE DE RESULTAT'!K13))*365) -> 22.915891
A94: Average Payment Days : (Sundry Creditors/Purchases * 365) | F94: =(PASSIF!D26/('COMPTE DE RESULTAT'!I5+'COMPTE DE RESULTAT'!I17+'COMPTE DE RESULTAT'!I19))*365 -> 12.36333 | G94: =(PASSIF!E26/('COMPTE DE RESULTAT'!J5+'COMPTE DE RESULTAT'!J17+'COMPTE DE RESULTAT'!J19))*365 -> 29.471722 | H94: =(PASSIF!F26/('COMPTE DE RESULTAT'!K5+'COMPTE DE RESULTAT'!K17+'COMPTE DE RESULTAT'!K19))*365 -> 12.501889
A95: Account Receivables Turnover: (Operating Income/Sundry Debtors) | F95: =('COMPTE DE RESULTAT'!I11+'COMPTE DE RESULTAT'!I13+'COMPTE DE RESULTAT'!I14+'COMPTE DE RESULTAT'!I15+'COMPTE DE RESULTAT'!I16)/ACTIF!G24 -> 12.710205 | G95: =('COMPTE DE RESULTAT'!J11+'COMPTE DE RESULTAT'!J13+'COMPTE DE RESULTAT'!J14+'COMPTE DE RESULTAT'!J15+'COMPTE DE RESULTAT'!J16)/ACTIF!H24 -> 10.575905 | H95: =('COMPTE DE RESULTAT'!K11+'COMPTE DE RESULTAT'!K13+'COMPTE DE RESULTAT'!K14+'COMPTE DE RESULTAT'!K15+'COMPTE DE RESULTAT'!K16)/ACTIF!I24 -> 15.927812
A96: Inventory Turnover: (Operating Income / Inventories) | F96: =('COMPTE DE RESULTAT'!I11+'COMPTE DE RESULTAT'!I13+'COMPTE DE RESULTAT'!I14+'COMPTE DE RESULTAT'!I15+'COMPTE DE RESULTAT'!I16)/ACTIF!G23 -> 5.8904505 | G96: =('COMPTE DE RESULTAT'!J11+'COMPTE DE RESULTAT'!J13+'COMPTE DE RESULTAT'!J14+'COMPTE DE RESULTAT'!J15+'COMPTE DE RESULTAT'!J16)/ACTIF!H23 -> 5.0543599 | H96: =('COMPTE DE RESULTAT'!K11+'COMPTE DE RESULTAT'!K13+'COMPTE DE RESULTAT'!K14+'COMPTE DE RESULTAT'!K15+'COMPTE DE RESULTAT'!K16)/ACTIF!I23 -> 12.666348
A97: Asset Turnover: (Operating Income / Net Fixed Assets) | F97: =('COMPTE DE RESULTAT'!I11+'COMPTE DE RESULTAT'!I13+'COMPTE DE RESULTAT'!I14+'COMPTE DE RESULTAT'!I15+'COMPTE DE RESULTAT'!I16)/ACTIF!G21 -> 60.12857 | G97: =('COMPTE DE RESULTAT'!J11+'COMPTE DE RESULTAT'!J13+'COMPTE DE RESULTAT'!J14+'COMPTE DE RESULTAT'!J15+'COMPTE DE RESULTAT'!J16)/ACTIF!H21 -> 38.633519 | H97: =('COMPTE DE RESULTAT'!K11+'COMPTE DE RESULTAT'!K13+'COMPTE DE RESULTAT'!K14+'COMPTE DE RESULTAT'!K15+'COMPTE DE RESULTAT'!K16)/ACTIF!I21 -> 47.88313
A122: LEVERAGE RATIOS | F122: N | G122: N-1 | H122: N-2
A123: Debt ratio: ((Borrowing + Current liab.)/Total assets) | F123: =(PASSIF!D15+PASSIF!D26)/ACTIF!G34 -> 0.10549232 | G123: =(PASSIF!E15+PASSIF!E26)/ACTIF!H34 -> 0.19504704 | H123: =(PASSIF!F15+PASSIF!F26)/ACTIF!I34 -> 0.16388611
A124: Debt Equity Ratio: (Borrowings / Net Worth) | F124: =PASSIF!D15/ACTIF!G21 -> 0 | G124: =PASSIF!E15/ACTIF!H21 -> 0 | H124: =PASSIF!F15/ACTIF!I21 -> 0
A125: Current Liabilities To Net Worth: (Current Liabilities / Net Worth) | F125: =PASSIF!D26/ACTIF!G21 -> 1.7483731 | G125: =PASSIF!E26/ACTIF!H21 -> 2.5803097 | H125: =PASSIF!F26/ACTIF!I21 -> 1.3920782
A126: Interest Coverage Ratio (PBIT / Financial Charges) | F126: ='COMPTE DE RESULTAT'!I37/'COMPTE DE RESULTAT'!I34 -> #DIV/0! | G126: ='COMPTE DE RESULTAT'!J37/'COMPTE DE RESULTAT'!J34 -> #DIV/0! | H126: ='COMPTE DE RESULTAT'!K37/'COMPTE DE RESULTAT'!K34 -> #DIV/0!
A147: SOLVENCY RATIOS | F147: N | G147: N-1 | H147: N-2
A148: Current Ratio: (Current Assets / Current Liabilities) | F148: =+ACTIF!G28/PASSIF!D26 -> 8.54425 | G148: =+ACTIF!H28/PASSIF!E26 -> 4.377993 | H148: =(ACTIF!I26+ACTIF!I27)/(PASSIF!F22+PASSIF!F23+PASSIF!F24) -> 2.1595476
A149: Quick Ratio: ((Current Assets - Inventories) / Current Liabilities) | F149: =(ACTIF!G28-ACTIF!G23)/PASSIF!D26 -> 2.7057908 | G149: =(ACTIF!H28-ACTIF!H23)/PASSIF!E26 -> 1.4157119 | H149: =(ACTIF!I28-ACTIF!I23)/PASSIF!F26 -> 2.1595476
A150: G-Score Ratio Financial: (Net Worth / Total Assets) | F150: =ACTIF!G18/ACTIF!G34 -> 0.035319465 | G150: =ACTIF!H18/ACTIF!H34 -> 0.038997706 | H150: =ACTIF!I18/ACTIF!I34 -> 0.034541121
A151: G-Score Ratio Debt: (Debts / Equity Capital) | F151: =PASSIF!D18/PASSIF!D14 -> 0 | G151: =PASSIF!E18/PASSIF!E14 -> 0 | H151: =PASSIF!F18/PASSIF!F14 -> 0
A152: G-Score Ratio Liquidity:(Total current assets / Total current liabilities) | F152: =ACTIF!G28/PASSIF!D26 -> 8.54425 | G152: =ACTIF!H28/PASSIF!E26 -> 4.377993 | H152: =ACTIF!I28/PASSIF!F26 -> 4.8751581

Sheet SCORING avec bilan saisi
A1: SCORE DE DEFAILLANCE ACREMAC
A3: BORNES | E3: Coeff. (1) | F3: Ratio | G3: Ratio | H3: Contribution
G4: limited (2) | H4: (1 X 2)
A5: - | B5: Constant | E5: 0.57 | H5: 0.57
A6: [0*;100] | B6: R1 = Frais financiers / EBITDA | E6: 0.0535 | F6: =(+E33) -> 0 | G6: =IF(F6<0,0,IF(F6>100,100,F6)) -> 0 | H6: =+E6*G6 -> 0
A7: [0;200] | B7: R2 = (Créances+débiteurs)/TC créanciers | E7: 0.0115 | F7: =(+E37) -> 208.1316 | G7: =IF(F7<0,0,IF(F7>200,200,F7)) -> 200 | H7: =+E7*G7 -> 2.3 | L7: Failure Score
A8: [-25;100] | B8: R3 = Capitaux permanents / Passif | E8: 0.0371 | F8: =(+E41) -> 84.444938 | G8: =IF(F8<-25,-25,IF(F8>100,100,F8)) -> 84.444938 | H8: =+E8*G8 -> 3.1329072
A9: [0;100] | B9: R4 = VA / AC | E9: 0.0246 | F9: =(+E45) -> 14.09673 | G9: =IF(F9<0,0,IF(F9>100,100,F9)) -> 14.09673 | H9: =+E9*G9 -> 0.34677955 | M9: N
A10: [-100;100] | B10: R5 = Trésorerie / Ventes (j) | E10: 0.0115 | F10: =+E49 -> 89.439566 | G10: =IF(F10<-100,-100,IF(F10>100,100,F10)) -> 89.439566 | H10: =+E10*G10 -> 1.028555 | J10: The crédit rating is expressed as an rating score with values of 0(Insolvency/preliminary/debt regulation proceedings) to 10 (excellent risk). The rating score denominates the probability of default for the company within 12 months from the date the rating score was set. Credit Rating: 10 Excellent risk, 9 Very low risk, 8 Low risk, 7 Moderate risk, 6 Acceptable risk, 5 Medium high risk, 4 Significant risk, 3 High risk , 2 Very high risk of insolvency, 1 Extremely high risk of insolvency, 0 Insolvency/preliminary/debt regulation proceedings
A11: [-100;150] | B11: R6 = Fonds de roulement / CA (j) | E11: 0.0096 | F11: =+E53 -> 77.805981 | G11: =IF(F11<-100,-100,IF(F11>150,150,F11)) -> 77.805981 | H11: =+E11*G11 -> 0.74693741
J14: Insolvency/preliminary/debt regulation proceedings | K14: Very High Risk | N14: Medium High Risk | P14: Low Risk
J15: 0 | K15: 1 | L15: 2 | M15: 3 | N15: 4 | O15: 5 | P15: 6 | Q15: 7 | R15: 8 | S15: 9 | T15: 10
A16: * Negative values are brought back to the upper limit
F18: Value of SCORE | H18: =SUM(H5:H11) -> 8.1251792 | J18: AUTOMATIC SCORE N | M18: =H18 -> 8.1251792
J19: AUTOMATIC SCORE N-1
A20: Score Classes | C20: Probability of failure(%) | E20: Conclusions | J20: AUTOMATIC SCORE N-2
A22: S<-4,01 | C22: >12,7 | J22: MANUAL SCORE N
A23: -4,01<S<-2,57 | C23: 6,00 | E23: High risk (failure rate >10%) | J23: MANUAL SCORE N-1
A24: -2,57<S<-1,00 | C24: 4.96 | J24: MANUAL SCORE N-2
A25: -1,00<S<0,28 | C25: 3.29
A26: 0,28<S<1,26 | C26: 2.15 | E26: Normal risk (default rate = 3%) | J26: Comment:
A27: 1,26<S<2,10 | C27: 1.57
A28: 2,10<S<2,86 | C28: 1.06 | J28: Key Score Factors : - R1 = Financial expenses / EBITDA - R2 = (Receivable+Disposable)/Creditors CT - R3 = Permanent capital / Liabilities - R4 = Added value / turnover - R5 = Cash / Sales (j) - R6 = Working capital / CA (j) Business credit scores range from a minimum of 1 to a maximum of 10. Higher scores indicate lower risk. This score predicts the likelihood of serious credit defaults over the next 12 months. This score uses transaction and collection information, public deposits, and other variables to predict future risk.
A29: 2,86<S<3,68 | C29: 0.64 | E29: Low risk (failure rate < 1%)
A30: 3,68<S<4,83 | C30: 0.38
A31: 5,83<S | C31: <0,42
A33: R1 = Financial expenses / EBITDA | E33: =(+B34/B35)*100 -> 0
A34: FFI | B34: ='COMPTE DE RESULTAT'!I34 -> 0
A35: EBE | B35: ='COMPTE DE RESULTAT'!I27 -> 38440330
A37: R2 = (Receivables + Cash) / Liabilities CT | E37: =(+B38/B39)*100 -> 208.1316
A38: Cré+disp net | B38: =ACTIF!G24+ACTIF!G32 -> 27499000
A39: CT debts | B39: =PASSIF!D26+PASSIF!D29 -> 13212314
A41: R3 = Permanent capital / Liabilities | E41: =(+B42/B43)*100 -> 84.444938
A42: Permanent course | B42: =PASSIF!D19 -> 71726686
A43: Liabilities | B43: =PASSIF!D31 -> 84939000
A45: R4 = VA / AC | E45: =(+B46/B47)*100 -> 14.09673
A46: VA | B46: ='COMPTE DE RESULTAT'!I25 -> 43440330
A47: CA | B47: ='COMPTE DE RESULTAT'!I11 -> 308158920
A49: R5 = Cash / Sales (j) | E49: =(+B50/B51) -> 89.439566
A50: Treasury | B50: =ACTIF!G28 -> 76560000
...

Sheet SCORING sans bilan
I1: Failure Score
A4: S1:The premises | B4: Grille | C4: 1 | D4: S4: Payment behaviour | E4: Grille | F4: -1
A5: Owner | B5: 1 | D5: In advance | E5: 1 | G5: This score is generated automatically through bucrep through the sumilations of the following items: The premises, Age of the company, Payment behaviour, Commercial opinion, Code Nace. The elements of the score grid have been weighted according to their degree of importance in the calculation of the risk. Credit Rating: 10 Excellent risk, 9 Very low risk, 8 Low risk, 7 Moderate risk, 6 Acceptable risk, 5 Medium high risk, 4 Significant risk, 3 High risk , 2 Very high risk of insolvency, 1 Extremely high risk of insolvency, 0 Insolvency/preliminary/debt regulation proceedings
A6: Tenant | B6: 0.5 | D6: In time | E6: 0.5
D7: Overdue | E7: 0
D8: Normal | E8: 0.25 | G8: Insolvency/preliminary/debt regulation proceedings | H8: Very High Risk | K8: Medium High Risk | M8: Low Risk
A9: S2: Legal form | B9: Grille | C9: 0.003 | D9: Bad payer | E9: -1 | G9: 0 | H9: 1 | I9: 2 | J9: 3 | K9: 4 | L9: 5 | M9: 6 | N9: 7 | O9: 8 | P9: 9 | Q9: 10
A10: anonimous company | B10: 1 | D10: Unknown | E10: 0 | H10: ↑ | I10: ↑ | J10: ↑ | K10: ↑ | L10: ↑ | M10: ↑ | N10: ↑ | O10: ↑ | P10: ↑ | Q10: ↑
A11: Limited liability company(SARL | B11: 0.75 | D11: Isolated complaint | E11: 0
A12: Individual company(EI) | B12: 0.05 | G12: AUTOMATIC SCORE | I12: =+C4+C9+C18+F4+F13+F19 -> 0.503
A13: One Person Limited liability company(SARL U) | B13: 0;50 | D13: S5 : Commercial opinion | E13: Grille | F13: 0 | H13: ACREMAC's Financial Stability Risk Assessment The objective of financial stability risk rating is to predict the probability of default and/or bankruptcy over the next 12 months. ACREMAC's Financial Stress Rating is calculated by a statistically derived algorithm designed to determine risk based on several factors including: transaction and collection information, public deposits and other variables to predict future risk.
A14: Branch | B14: 0.005 | D14: Negative | E14: 0
A15: Government body | B15: 0.005 | D15: Medium | E15: 0.25
A16: Other legal form | B16: 0.003 | D16: Good | E16: 0.5
D17: Very Good | E17: 0.75
A18: S3: Age of the company | B18: Grille | C18: 0
A19: New company | B19: 0 | D19: S6 : Code Nace | E19: Grille | F19: 0.5
A20: ≤ 2 years | B20: 0.1 | D20: Manifacture | E20: 0.75
A21: 2-4 years old | B21: 0.2 | D21: Wholesale | E21: 0.5
A22: 5-6 years old | B22: 0.4 | D22: Services | E22: 0.5
A23: 7-8 years old | B23: 0.6
A24: 9-10 years old | B24: 0.8
A25: < 10 years | B25: 1
