Workbook

Sheet Fiche identité société
A3: Raison sociale: SUPER U
A4: Enseigne:SUPER U
A5: Siège social: 180 ALL DES NOYERES RD 1205 - ROND POINT DE BALME 74300 MAGLAND - FRANCE
A6: Téléphone: +33 4 50 18 98 ..
A7: INFORMATIONS JURIDIQUES
A8: Forme Juridique: 5710 - Société par actions simplifiée (SAS)
A9: Capital Socia: 1 250 000 €
A10: RCS: ANNECY siren 111111111
A11: N° de T.V.A: FR 74 111111111
A12: Catégorie: Petite ou Moyenne Entreprise
A13: Date de création: 14/11/2013
A14: Activité principale: 4711D - Supermarchés
... A22: Groupe super U ( siren 222 222 222)

Sheet ACTIF
A2: ACTIF (Fiche 1)
C3: en K€
C5: 44196 | D5: 44561
A7: Capital souscrit non appele | B7: AA* | C7: 0 | D7: 0
A9: ACTIF IMMOBILISE
A11: Frais d'etablissement | B11: AB* | C11: 0 | D11: 0
A12: Frais de R et D | B12: AD* | C12: 0 | D12: 0
A13: Concessions, brevets | B13: AF* | C13: 1.08 | D13: 4.19
A14: Fonds commercial | B14: AH* | C14: 0 | D14: 0
A15: Autres immos incorporelles | B15: AJ* | C15: 69.85 | D15: 58.21
A16: Avances et acptes / imm. inc. | B16: AL* | C16: 0 | D16: 0
A18: Terrains | B18: AN* | C18: 2229.87 | D18: 2157.03
A19: Constructions | B19: AP* | C19: 3983.51 | D19: 3449.11
A20: Instal. techn., mat. et out. | B20: AR* | C20: 150.96 | D20: 249.22
A21: Autres immos corporelles | B21: AT* | C21: 131.38 | D21: 130.6
A22: Immobilisations en cours | B22: AV* | C22: 0 | D22: 0
A23: Avances et acptes / imm. corp. | B23: AX* | C23: 0 | D23: 0
... A30: TOTAL (I) | B30: BJ* | C30: 6860.85 | D30: 6340.97
A32: STOCKS :
A33: Matieres premieres, approv. | B33: BL* | C33: 0 | D33: 4.74
A34: En cours prod. biens | B34: BN* | C34: 0 | D34: 0 | I34: 2021
A35: En cours prod. services | B35: BP* | C35: 0 | D35: 0
A36: Produits intermediaires | B36: BR* | C36: 0 | D36: 0 | I36: brut | J36: dep | K36: Net
A37: Marchandises | B37: BT* | C37: 1876.41 | D37: 1758.19 | G37: Marchandises | I37: 1913 | J37: 155 | K37: =I37-J37 -> 1758
A39: Avances et acptes sur cmdes | B39: BV* | C39: 5 | D39: 0
A41: Clients et cptes rattaches | B41: BX* | C41: 102.06 | D41: 108.93 | I41: 2020
A42: Autres creances | B42: BZ* | C42: 853.56 | D42: 438.07 | I42: brut | J42: dep | K42: Net
A43: Capital sousc. appele non verse | B43: CB* | C43: 0 | D43: 0 | G43: Marchandises | I43: 2048 | J43: 172 | K43: =I43-J43 -> 1876
A45: Valeurs mobilieres de placement | B45: CD* | C45: 1280.15 | D45: 315.29
A46: Disponibilites | B46: CF* | C46: 4937.04 | D46: 6105.2
A47: Charges constatees d'avance | B47: CH* | C47: 69.85 | D47: 127.72
A48: TOTAL (II) | B48: CJ* | C48: 9124.07 | D48: 8858.15
A50: Charges a repartir | B50: CL* | C50: 0 | D50: 0
A51: Primes de remboursement oblig. | B51: CM* | C51: 0 | D51: 0
A52: Ecarts conversion actif | B52: CN* | C52: 182.61 | D52: 167.34
A54: TOTAL GENERAL | B54: CO* | C54: 16167.53 | D54: 15366.46
A55: (2) Part moins d'un an immo Fin | B55: CO1

Sheet Feuil2

Sheet PASSIF
A3: PASSIF (Fiche 2)
B4: en K€
C6: 44196 | D6: 44561
A8: Capital social ou individuel | B8: DA | C8: 1250 | D8: 1250
A9: Primes emission, fusion, apport | B9: DB | C9: 0 | D9: 0
A10: Ecart de reevaluation | B10: DC | C10: 0 | D10: 0
A11: Reserve legale | B11: DD | C11: 125 | D11: 125
A12: Reserves statut. ou contract. | B12: DE | C12: 0 | D12: 0
A13: Reserves reglementees | B13: DF | C13: 0 | D13: 0
A14: Autres reserves | B14: DG | C14: 3547.13 | D14: 2271.18
A15: Report a nouveau | B15: DH | C15: 0 | D15: 0
A16: RESULTAT DE L'EXERCICE | B16: DI | C16: 1724.04 | D16: 2363.87
A17: Subventions d'investissement | B17: DJ | C17: 0 | D17: 0
A18: Provisions reglementees | B18: DK | C18: 1.02 | D18: 1.68
A20: TOTAL (I) Capitaux propres | B20: DL | C20: 6647.2 | D20: 6011.73
... A34: Dettes bancaires | B34: DU | C34: 3891 | D34: 3292
A35: Concours bancaires | C35: 82 | D35: 111
A36: Emp. & dettes fin. Divers ( dt 958 comptes courants associés bloqués) | B36: DV | C36: 971.43 | D36: 958
A37: Avances et acomptes / cmdes | B37: DW | C37: 0 | D37: 0
A38: Dettes fournisseurs | B38: DX | C38: 2865.69 | D38: 3111.4
A39: Dettes fiscales et sociales | B39: DY | C39: 1342.69 | D39: 1706.98
A40: Dettes sur immobilisations | B40: DZ | C40: 78.57 | D40: 0
A41: Autres dettes | B41: EA | C41: 8.07 | D41: 7.96
A42: Produits constates d'avance | B42: EB | C42: 0 | D42: 0
A44: TOTAL (IV) | B44: EC | C44: 9239.72 | D44: 9187.39
A46: Ecart conv. passif (V) | B46: ED | C46: 0 | D46: 0
A48: TOTAL GENERAL ( I a V ) | B48: EE | C48: 16167.53 | D48: 15366.46
A51: Renvois
A52: (6) Dont concours bancaires | B52: EH | C52: 0 | D52: 0
A53: (7) Dont emprunts participatifs et CC bloqués | B53: EI | C53: 0 | D53: 0

Sheet Compte de résultat 
A3: COMPTE DE RESULTAT (Fiche 3)
C4: en K€
C6: 44196 | D6: 44561
A8: Ventes de marchandises | B8: FC | C8: 53412.15 | D8: 51969.6
A9: Production vendue, biens | B9: FF | C9: 0 | D9: 0
A10: Production vendue, services | B10: FI | C10: 807.35 | D10: 810.4
A11: Chiffres d'affaires net | B11: FL | C11: 54219.5 | D11: 52780
A12: Production stockee | B12: FM | C12: 0 | D12: 0
A13: Production immobilisee | B13: FN | C13: 0 | D13: 0
A14: Subvention d'exploitation | B14: FO | C14: 0 | D14: 0
A15: Reprises amortiss. + provisions | B15: FP | C15: 265.45 | D15: 259.47
A16: Autres produits | B16: FQ | C16: 17.09 | D16: 25.29
A17: TOTAL pdts d'expl. (I) | B17: FR | C17: 54502.04 | D17: 53064.76
A19: Achats de marchandises | B19: FS | C19: 43194.43 | D19: 40186.52
A20: Variation de stock march. | B20: FT | C20: -18.42 | D20: 135.5
... A76: BENEFICE OU PERTE | B76: HN | C76: 1724.04 | D76: 2363.87
A79: Renvois
A80: (3)Dont -Credit bail mobilier | B80: HP | C80: 0 | D80: 0
A81: -Credit bail immobilier | B81: HQ | C81: 0 | D81: 0
A83: Transfert de charges | B83: A1 | C83: 62 | D83: 100
A84: intérêts titres | B84: 1K | C84: 11.46 | D84: 0

Sheet RES04
A1: =#REF! -> #REF!
A3: COMPTE DE RESULTAT (Fiche 4)
A6: ="POSTES " &#REF! -> #REF! | C6: =+#REF! -> #REF! | D6: =+#REF! -> #REF! | E6: =+#REF! -> #REF!
A8: Produits except.: ope. gestion | B8: HA | D8: 146.09 | E8: 95.02
A9: Produits except.: ope. capital | B9: HB | D9: 0 | E9: 0
A10: Reprises sur provisions | B10: HC | D10: 10.62 | E10: 298.04
A11: Total produits except. (VII) | B11: HD | D11: 156.71 | E11: 393.06
A13: Charges except.: ope. gestion | B13: HE | D13: 6.47 | E13: 0.69
A14: Charges except.: ope. capital | B14: HF | D14: 0 | E14: 200.73
A15: Dotations exceptionnelles | B15: HG | D15: 318.48 | E15: 0.7
A16: Total charges except. (VIII) | B16: HH | D16: 324.95 | E16: 202.12
A18: RESULTAT EXCEPTIONNEL | B18: HI | D18: -168.24 | E18: 190.94
A20: Participation des salaries (IX) | B20: HJ | D20: 284.19 | E20: 354.06
A21: Impot sur les benefices (X) | B21: HK | D21: -220.34 | E21: 245.74
A23: TOTAL PRODUITS (I+III+V+VII) | B23: HL | D23: 54734.13 | E23: 53671.87
... A27: BENEFICE OU PERTE | B27: HN | D27: 1724.04 | E27: 2363.87
A30: Renvois
A31: (3)Dont -Credit bail mobilier | B31: HP | D31: 0 | E31: 0
A32: -Credit bail immobilier | B32: HQ | D32: 0 | E32: 0
A34: Transfert de charges | B34: A1 | D34: 63.44 | E34: 0
A35: intérêts titres | B35: 1K | D35: 11.46 | E35: 0

Sheet Calcul ratio
B1: Le Fonds de Roulement (FR) , le Besoin en Fonds de Roulement (BFR) et la trésorerie Nette (TN)
B2: Année | C2: 2020 | D2: 2021
B3: Ressources stables | C3: =PASSIF!C20+PASSIF!C30+PASSIF!C34+PASSIF!C36 -> 11790.24 | D3: =PASSIF!D20+PASSIF!D30+PASSIF!D34+PASSIF!D36 -> 10429.07 | F3: Comptes courants d'associés bloqués ==> quasi fonds propres
B4: Emplois stables | C4: =ACTIF!C30 -> 6860.85 | D4: =ACTIF!D30 -> 6340.97
B6: FR | C6: =C3-C4 -> 4929.39 | D6: =D3-D4 -> 4088.1
B7: FR en jrs de CA | C7: =C6/'Compte de résultat '!C8*360 -> 33.224283 | D7: =D6/'Compte de résultat '!D8*360 -> 28.318786
B10: Actif circulant | C10: =ACTIF!C48+ACTIF!C52-ACTIF!C45-ACTIF!C46 -> 3089.49 | D10: =ACTIF!D48+ACTIF!D52-ACTIF!D45-ACTIF!D46 -> 2605
B11: Passif circulant | C11: =PASSIF!C44-PASSIF!C36-PASSIF!C35-PASSIF!C34 -> 4295.29 | D11: =PASSIF!D44-PASSIF!D36-PASSIF!D35-PASSIF!D34 -> 4826.39
B12: BFR | C12: =C10-C11 -> -1205.8 | D12: =D10-D11 -> -2221.39
B13: BFR en jrs de CA | C13: =C12/'Compte de résultat '!C8*360 -> -8.1271396 | D13: =D12/'Compte de résultat '!D8*360 -> -15.38785
B16: TN ( FR-BFR) | C16: =C6-C12 -> 6135.19 | D16: =D6-D12 -> 6309.49
B17: TN ( disponibilités - concours bancaire) | C17: =ACTIF!C45+ACTIF!C46-PASSIF!C35 -> 6135.19 | D17: =ACTIF!D45+ACTIF!D46-PASSIF!D35 -> 6309.49
B18: TN en Jrs de CA | C18: =C16/'Compte de résultat '!C11*360 -> 40.735684 | D18: =D16/'Compte de résultat '!D11*360 -> 43.035551
B22: La capacité d’autofinancement (CAF )
B24: Année | C24: 2020 | D24: 2021
B25: Résultat net | C25: ='RES04'!D27 -> 1724.04 | D25: ='RES04'!E27 -> 2363.87
B26: +Dotation aux amortissement | C26: =SUM(C27:C29) -> 1789.73 | D26: =SUM(D27:D29) -> 557.91
B27: exploitation | C27: ='Compte de résultat '!C27+'Compte de résultat '!C28+'Compte de résultat '!C29+'Compte de résultat '!C30 -> 967.42 | D27: 21
B28: financière | C28: ='Compte de résultat '!C47 -> 503.83 | D28: ='Compte de résultat '!D47 -> 536.21
B29: exceptionnelle | C29: ='Compte de résultat '!C64 -> 318.48 | D29: ='Compte de résultat '!D64 -> 0.7
B30: - Reprise de provisions, les reprises d’amortissement | C30: =SUM(C31:C33) -> 246.24 | D30: =SUM(D31:D33) -> 472.78 | G30: Attention dans le compte reprise il y a des transferts de charges 62ke en 2021 et 100ke en 2020
B31: exploitation | C31: ='Compte de résultat '!C15-'Compte de résultat '!C83 -> 203.45 | D31: ='Compte de résultat '!D15-'Compte de résultat '!D83 -> 159.47
B32: financière | C32: ='Compte de résultat '!C42 -> 32.17 | D32: ='Compte de résultat '!D42 -> 15.27
B33: exceptionnelle | C33: ='Compte de résultat '!C59 -> 10.62 | D33: ='Compte de résultat '!D59 -> 298.04 | H33: ,
B34: + Valeur nette comptable d'éléments d'actifs | C34: ='Compte de résultat '!C63 -> 0 | D34: ='Compte de résultat '!D63 -> 200.73
B35: - Produits de cession des éléments d'actifs | C35: ='RES04'!D9 -> 0 | D35: ='RES04'!E9 -> 0
B37: CAF | C37: =C25+C26-C30+C34-C35 +100 -> 3367.53 | D37: =D25+D26-D30+D34-D35+62 -> 2711.73
B38: CAF retraité except | C38: =C25+C26-C30 -> 3267.53 | D38: =D25+D26-D30 -> 2449 | G38: Hypothése ==> except font parties de l'activité courante (exemple pour les loueurs)
B41: Les ratios de marge
B43: Année | C43: 2020 | D43: 2021
B44: CA | C44: ='Compte de résultat '!C11 -> 54219.5 | D44: ='Compte de résultat '!D11 -> 52780
B45: EBE | C45: ='Compte de résultat '!C11-('Compte de résultat '!C19+'Compte de résultat '!C20+'Compte de résultat '!C21+'Compte de résultat '!C22+'Compte de résultat '!C23+'Compte de résultat '!C24+'Compte de résultat '!C25+'Compte de résultat '!C26)+'Compte de résultat '!C14 -> 3263.38 | D45: ='Compte de résultat '!D11-('Compte de résultat '!D19+'Compte de résultat '!D20+'Compte de résultat '!D21+'Compte de résultat '!D22+'Compte de résultat '!D23+'Compte de résultat '!D24+'Compte de résultat '!D25+'Compte de résultat '!D26)+'Compte de résultat '!D14 -> 3977.79
B46: Rex | C46: ='Compte de résultat '!C34 -> 2565.94 | D46: ='Compte de résultat '!D34 -> 3348.34
B47: RN | C47: ='RES04'!D27 -> 1724.04 | D47: ='RES04'!E27 -> 2363.87
B48: Marge brute d’exploitation: EBE / CA | C48: =C45/C44 -> 0.060188309 | D48: =D45/D44 -> 0.075365479 | E48: En 2021 Pour 1 € de vente la sté réalise 0,08 de marge après paiement des fournisseurs et des salaires
B49: Marge nette d’exploitation: Résultat d’exploitation / CA | C49: =C46/C44 -> 0.04732504 | D49: =D46/D44 -> 0.06343956 | E49: En 2021 Pour 1 € de vente la sté réalise 0,06 de marge après après déductions de tous les coûts de production
B50: Taux de marge nette: Résultat net / CA | C50: =C47/C44 -> 0.031797416 | D50: =D47/D44 -> 0.04478723 | E50: En 2021 Pour 1 € de vente la sté réalise 0,04 de résultat net
I52: 2021 | K52: 2020
B55: Les ratios de rotation de stocks | G55: Varition stcoks | I55: =I62-I68 -> -135.5 | K55: =I68-I74 -> 18
G57: conf compte de résultat
...

Sheet Soldes Interm.
A2: SOLDES INTERMEDIAIRES DE GESTION
F4: Var, ( 21/20) %
B5: 44196 | C5: % | D5: 44561 | E5: %
A7: Ventes de march. | B7: ='Compte de résultat '!C8 -> 53412.15 | D7: ='Compte de résultat '!D8 -> 51969.6
A8: Production vendue | B8: ='Compte de résultat '!C9+'Compte de résultat '!C10 -> 807.35 | D8: ='Compte de résultat '!D9+'Compte de résultat '!D10 -> 810.4
A10: 1. Chiffre d'Affaires | B10: =B7+B8 -> 54219.5 | D10: =D7+D8 -> 52780 | F10: =IF(B10=0,0,(D10-B10)*100/B10) -> -2.6549489
A12: Production vendue | B12: =B8 -> 807.35 | D12: =D8 -> 810.4
A13: Production stockee | B13: ='Compte de résultat '!C12 -> 0 | D13: ='Compte de résultat '!D12 -> 0
A14: Production immo. | B14: ='Compte de résultat '!C13 -> 0 | D14: ='Compte de résultat '!D13 -> 0
A16: 2. Prod. de l'exercice | B16: =SUM(B12:B14) -> 807.35 | C16: =IF(B16=0,0,+B16*100/B$10) -> 1.4890399 | D16: =SUM(D12:D14) -> 810.4 | E16: =IF(D16=0,0,+D16*100/D$10) -> 1.5354301 | F16: =IF(B16=0,0,(D16-B16)*100/B16) -> 0.37777915
A18: Ventes de march. | B18: =B7 -> 53412.15 | D18: =D7 -> 51969.6
A19: - Ct ach. march. vend. | B19: ='Compte de résultat '!C19+'Compte de résultat '!C20 -> 43176.01 | D19: ='Compte de résultat '!D19+'Compte de résultat '!D20 -> 40322.02
A21: 3. Marge commerciale | B21: =B18-B19 -> 10236.14 | C21: =IF(B21=0,0,+B21*100/B$10) -> 18.879075 | D21: =D18-D19 -> 11647.58 | E21: =IF(D21=0,0,+D21*100/D$10) -> 22.06817 | F21: =IF(B21=0,0,(D21-B21)*100/B21) -> 13.788791
A23: Prod. de l'exercice | B23: =B16 -> 807.35 | D23: =D16 -> 810.4
A24: Marge commerciale | B24: =B21 -> 10236.14 | D24: =D21 -> 11647.58
A25: - Conso. des Tiers | B25: =SUM('Compte de résultat '!C21:C23)-SUM('RES04'!D31:D32) -> 3988.86 | D25: =SUM('Compte de résultat '!D21:D23)-SUM('RES04'!E31:E32) -> 4397.83
A27: 4. Valeur Ajoutee | B27: =B23+B24-B25 -> 7054.63 | C27: =IF(B27=0,0,+B27*100/B$10) -> 13.011241 | D27: =D23+D24-D25 -> 8060.15 | E27: =IF(D27=0,0,+D27*100/D$10) -> 15.27122 | F27: =IF(B27=0,0,(D27-B27)*100/B27) -> 14.253334
A29: Valeur ajoutee | B29: =B27 -> 7054.63 | D29: =D27 -> 8060.15
A30: Subvention d'expl. | B30: ='Compte de résultat '!C14 -> 0 | D30: ='Compte de résultat '!D14 -> 0
A31: - Impots et taxes | B31: ='Compte de résultat '!C24 -> 435.92 | D31: ='Compte de résultat '!D24 -> 448.73
A32: - Charges de person. | B32: ='Compte de résultat '!C25+'Compte de résultat '!C26 -> 3355.33 | D32: ='Compte de résultat '!D25+'Compte de résultat '!D26 -> 3633.63
A34: 5. Excedent Brut d'Expl. | B34: =B29+B30-B31-B32 -> 3263.38 | C34: =IF(B34=0,0,+B34*100/B$10) -> 6.0188309 | D34: =D29+D30-D31-D32 -> 3977.79 | E34: =IF(D34=0,0,+D34*100/D$10) -> 7.5365479 | F34: =IF(B34=0,0,(D34-B34)*100/B34) -> 21.89172
A36: EBE | B36: =B34 -> 3263.38 | D36: =D34 -> 3977.79
A37: - Dot. amt. prv. exp. | B37: =-SUM('Compte de résultat '!C27:C30)-2/3*'RES04'!D31-1/2*'RES04'!D32 -> -967.42 | D37: =-SUM('Compte de résultat '!D27:D30)-2/3*'RES04'!E31-1/2*'RES04'!E32 -> -902.51
A38: Rep/amt. + transf. | B38: ='Compte de résultat '!C15 -> 265.45 | D38: ='Compte de résultat '!D15 -> 259.47
A39: +/-Aut. pdt. ch. gest. | B39: ='Compte de résultat '!C16-'Compte de résultat '!C31 -> 4.54 | D39: ='Compte de résultat '!D16-'Compte de résultat '!D31 -> 13.58
A41: 6. Resultat d'expl. | B41: =SUM(B36:B39) -> 2565.95 | C41: =IF(B41=0,0,+B41*100/B$10) -> 4.7325224 | D41: =SUM(D36:D39) -> 3348.33 | E41: =IF(D41=0,0,+D41*100/D$10) -> 6.3439371 | F41: =IF(B41=0,0,(D41-B41)*100/B41) -> 30.490851
A43: Resultat d'expl. | B43: =B41 -> 2565.95 | D43: =D41 -> 3348.33
A44: +/-Qu.pt/op. en commun | B44: ='Compte de résultat '!C36-'Compte de résultat '!C37 -> -101.67 | D44: ='Compte de résultat '!D36-'Compte de résultat '!D37 -> -56.43
A45: +/-Pdt. et ch. fin. | B45: ='Compte de résultat '!C53 -> -508.13 | D45: ='Compte de résultat '!D53 -> -519.17
A46: - Loyers credit bail | B46: =-1/3*'RES04'!D31-1/2*'RES04'!D32 -> 0 | D46: =-1/3*'RES04'!E31-1/2*'RES04'!E32 -> 0
A48: 7. Resultat courant | B48: =SUM(B43:B46) -> 1956.15 | C48: =IF(B48=0,0,+B48*100/B$10) -> 3.6078348 | D48: =SUM(D43:D46) -> 2772.73 | E48: =IF(D48=0,0,+D48*100/D$10) -> 5.2533725 | F48: =IF(B48=0,0,(D48-B48)*100/B48) -> 41.744243
A50: Resultat courant | B50: =B48 -> 1956.15 | D50: =D48 -> 2772.73
A51: +/-Resultat except. | B51: ='RES04'!D18 -> -168.24 | D51: ='RES04'!E18 -> 190.94
A52: - Part. des salaries | B52: =-'RES04'!D20 -> -284.19 | D52: =-'RES04'!E20 -> -354.06
A53: - IS | B53: =-'RES04'!D21 -> 220.34 | D53: =-'RES04'!E21 -> -245.74
A55: 8. Resultat de l'exerc. | B55: =SUM(B50:B53) -> 1724.06 | C55: =IF(B55=0,0,+B55*100/B$10) -> 3.1797785 | D55: =SUM(D50:D53) -> 2363.87 | E55: =IF(D55=0,0,+D55*100/D$10) -> 4.478723 | F55: =IF(B55=0,0,(D55-B55)*100/B55) -> 37.110657
